<?xml version="1.0"?>
<robot name="pffrobot">
  <link name="base_link">
    <visual>
      <geometry>
        <cylinder length="0.5" radius="0.3"/>
      </geometry>
      <origin rpy="1.5705 0 0" xyz="0 0 0.45"/>
      <material name="green">
        <color rgba="0 1 0 1"/>
      </material>
    </visual>
    <collision>
      <geometry>
        <cylinder length="0.5" radius="0.3"/>
      </geometry>
    </collision>
    <inertial>
          <mass value="1"/>
        <inertia ixx="1.0" iyy="1.0" izz="1.0" ixy="0.0" ixz="0.0" iyz="0.0"/>
        </inertial>
  </link>
  <link name="leftwheel">
    <visual>
      <geometry>
        <cylinder length="0.05" radius="0.45"/>
      </geometry>
      <origin rpy="1.5705 0 0" xyz="0 0 0"/>
      <material name="black">
        <color rgba="0 0 0 1"/>
      </material>
    </visual>
    <collision>
      <geometry>
        <cylinder length="0.05" radius="0.45"/>
      </geometry>
    </collision>
    <inertial>
          <mass value="1"/>
        <inertia ixx="1.0" iyy="1.0" izz="1.0" ixy="0.0" ixz="0.0" iyz="0.0"/>
        </inertial>
  </link>
  <joint name="base_to_leftwheel" type="continuous">
    <parent link="base_link"/>
    <child link="leftwheel"/>
    <origin xyz="0 0.25 0.45"/>
  </joint>
  <link name="rightwheel">
    <visual>
      <geometry>
        <cylinder length="0.05" radius="0.45"/>
      </geometry>
      <origin rpy="1.5705 0 0" xyz="0 0 0"/>
      <material name="black">
        <color rgba="0 0 0 1"/>
      </material>
    </visual>
    <collision>
      <geometry>
        <cylinder length="0.05" radius="0.45"/>
      </geometry>
    </collision>
    <inertial>
          <mass value="1"/>
        <inertia ixx="1.0" iyy="1.0" izz="1.0" ixy="0.0" ixz="0.0" iyz="0.0"/>
        </inertial>
  </link>
  <joint name="base_to_rightwheel" type="continuous">
    <parent link="base_link"/>
    <child link="rightwheel"/>
    <origin xyz="0 -0.25 0.45"/>
  </joint>
  <gazebo>
    <plugin name="differential_drive_controller" filename="libgazebo_ros_diff_drive.so">
    <alwaysOn>true</alwaysOn>
    <updateRate>100.0</updateRate>
    <leftJoint>base_to_lwheel</leftJoint>
    <rightJoint>base_to_rwheel</rightJoint>
    <wheelSeparation>0.5</wheelSeparation>
    <wheelDiameter>0.90</wheelDiameter>
    <torque>20</torque>
    <commandTopic>cmd_vel</commandTopic>
    <robotBaseFrame>base_link</robotBaseFrame>
  </plugin>
</gazebo>
</robot>
